Traceback (most recent call last):
  File "C:\Users\RYZEN\AppData\Local\Programs\Python\Python311\Lib\site-packages\jupyter_cache\executors\utils.py", line 58, in single_nb_execution
    executenb(
  File "C:\Users\RYZEN\AppData\Local\Programs\Python\Python311\Lib\site-packages\nbclient\client.py", line 1314, in execute
    return NotebookClient(nb=nb, resources=resources, km=km, **kwargs).execute()
           ^^^^^^^^^^^^^^^^^^^^^^^^^^^^^^^^^^^^^^^^^^^^^^^^^^^^^^^^^^^^^^^^^^^^^
  File "C:\Users\RYZEN\AppData\Local\Programs\Python\Python311\Lib\site-packages\jupyter_core\utils\__init__.py", line 165, in wrapped
    return loop.run_until_complete(inner)
           ^^^^^^^^^^^^^^^^^^^^^^^^^^^^^^
  File "C:\Users\RYZEN\AppData\Local\Programs\Python\Python311\Lib\asyncio\base_events.py", line 654, in run_until_complete
    return future.result()
           ^^^^^^^^^^^^^^^
  File "C:\Users\RYZEN\AppData\Local\Programs\Python\Python311\Lib\site-packages\nbclient\client.py", line 709, in async_execute
    await self.async_execute_cell(
  File "C:\Users\RYZEN\AppData\Local\Programs\Python\Python311\Lib\site-packages\nbclient\client.py", line 1062, in async_execute_cell
    await self._check_raise_for_error(cell, cell_index, exec_reply)
  File "C:\Users\RYZEN\AppData\Local\Programs\Python\Python311\Lib\site-packages\nbclient\client.py", line 918, in _check_raise_for_error
    raise CellExecutionError.from_cell_and_msg(cell, exec_reply_content)
nbclient.exceptions.CellExecutionError: An error occurred while executing the following cell:
------------------
df['Harga'] = df['Harga'].replace('-', np.nan).str.replace(',', '').astype(float)
print(df.head())
------------------


[1;31m-----------------------------------------------------[0m
[1;31mNameError[0m           Traceback (most recent call last)
Cell [1;32mIn[4], line 1[0m
[1;32m----> 1[0m df[[38;5;124m'[39m[38;5;124mHarga[39m[38;5;124m'[39m] [38;5;241m=[39m df[[38;5;124m'[39m[38;5;124mHarga[39m[38;5;124m'[39m][38;5;241m.[39mreplace([38;5;124m'[39m[38;5;124m-[39m[38;5;124m'[39m, [43mnp[49m[38;5;241m.[39mnan)[38;5;241m.[39mstr[38;5;241m.[39mreplace([38;5;124m'[39m[38;5;124m,[39m[38;5;124m'[39m, [38;5;124m'[39m[38;5;124m'[39m)[38;5;241m.[39mastype([38;5;28mfloat[39m)
[0;32m      2[0m [38;5;28mprint[39m(df[38;5;241m.[39mhead())

[1;31mNameError[0m: name 'np' is not defined

